Workbook
Name jobcode: 'Job code'!#REF!

Sheet Phòng
A1: Nguyễn Văn Thuận | B1: ADM
A2: Nguyễn Minh Tiến | B2: RDI
A3: Trần Tuấn Anh | B3: QC
A4: Vương Thị Hải Thanh | B4: HR
A5: Nguyễn Trọng Phi | B5: IT
A6: Nghiêm Xuân Thành | B6: AUTO
A7: Trần Đức Hải | B7: RDI
A8: Trần Việt Lâm | B8: AUTO
A9: Nguyễn Thị Hòa | B9: PUR
A10: Vũ Minh Đức | B10: RDS
A11: Phí Văn Tuấn | B11: AUTO
A12: Trương Thị Thanh | B12: ACC
... A179: Nguyễn Xuân Đức | B179: IT

Sheet Job code
A4: STT | B4: CODE
A5: =ROW()-ROW($A$4) -> 1 | B5: Annual Leave
A6: =ROW()-ROW($A$4) -> 2 | B6: Other
A7: =ROW()-ROW($A$4) -> 3 | B7: QLC
A8: =ROW()-ROW($A$4) -> 4 | B8: MEC1808001
A9: =ROW()-ROW($A$4) -> 5 | B9: MEC1808003
A10: =ROW()-ROW($A$4) -> 6 | B10: MEC1809002
A11: =ROW()-ROW($A$4) -> 7 | B11: MEC1810001
A12: =ROW()-ROW($A$4) -> 8 | B12: MEC1810002
A13: =ROW()-ROW($A$4) -> 9 | B13: MEC1810004
A14: =ROW()-ROW($A$4) -> 10 | B14: MEC1810005
A15: =ROW()-ROW($A$4) -> 11 | B15: MEC1810007
A16: =ROW()-ROW($A$4) -> 12 | B16: MEC1812005
... A513: =ROW()-ROW($A$4) -> 509 | B513: MEC2407005
A514: 915 | B514: MEC2407007
A515: =ROW()-ROW($A$4) -> 511 | B515: MEC2407010
A516: =ROW()-ROW($A$4) -> 512 | B516: MEC2407011
A517: =ROW()-ROW($A$4) -> 513 | B517: MEC2407014
A518: =ROW()-ROW($A$4) -> 514 | B518: MEC2407015
A519: =ROW()-ROW($A$4) -> 515 | B519: MEC2407020
A520: =ROW()-ROW($A$4) -> 516 | B520: PM103110
A521: =ROW()-ROW($A$4) -> 517 | B521: MEC2407027
A522: =ROW()-ROW($A$4) -> 518 | B522: MEC2407029
A523: =ROW()-ROW($A$4) -> 519 | B523: MEC2407035
A524: =ROW()-ROW($A$4) -> 520 | B524: MEC2407036
A525: =ROW()-ROW($A$4) -> 521 | B525: MEC2407037
A526: =ROW()-ROW($A$4) -> 522 | B526: MEC2407038
... A592: =ROW()-ROW($A$4) -> 588 | B592: MEC2409101
A593: 860B | B593: MEC2409102
A594: =ROW()-ROW($A$4) -> 590 | B594: MEC2410005
A595: =ROW()-ROW($A$4) -> 591 | B595: MEC2410006
A596: =ROW()-ROW($A$4) -> 592 | B596: MEC2410008
A597: =ROW()-ROW($A$4) -> 593 | B597: MEC2410009
A598: =ROW()-ROW($A$4) -> 594 | B598: MEC2410021
A599: =ROW()-ROW($A$4) -> 595 | B599: MEC2410022
A600: =ROW()-ROW($A$4) -> 596 | B600: MEC2410023
A601: =ROW()-ROW($A$4) -> 597 | B601: MEC2410024
A602: =ROW()-ROW($A$4) -> 598 | B602: MEC2410026
A603: =ROW()-ROW($A$4) -> 599 | B603: MEC2410037
A604: =ROW()-ROW($A$4) -> 600 | B604: MEC2410045
...

Sheet JOB DONE
D2: dsd
A4: STT | B4: Job done | C4: Code & Name | D4: Code & Name | E4: PIC | F4: PO | G4: Phòng ban thực hiện | H4: Note
A5: =ROW()-ROW($A$4) -> 1 | B5: MEC1806001 | C5: Improve soldering robot Lether-α | D5: =IF(E5="Guarantee",E5&"||"&B5&"||"&C5,B5&"||"&C5) -> MEC1806001||Improve soldering robot Lether-α
A6: =ROW()-ROW($A$4) -> 2 | B6: MEC1804003 | C6: Sheet Unloading Machine | D6: =IF(E6="Guarantee",E6&"||"&B6&"||"&C6,B6&"||"&C6) -> MEC1804003||Sheet Unloading Machine
A7: =ROW()-ROW($A$4) -> 3 | B7: MEC1806002 | C7: MSC-18A Video Controller | D7: =IF(E7="Guarantee",E7&"||"&B7&"||"&C7,B7&"||"&C7) -> MEC1806002||MSC-18A Video Controller
A8: =ROW()-ROW($A$4) -> 4 | B8: MEC1804006 | C8: R&D DC current and Voltage monitoring solution | D8: =IF(E8="Guarantee",E8&"||"&B8&"||"&C8,B8&"||"&C8) -> MEC1804006||R&D DC current and Voltage monitoring solution
A9: =ROW()-ROW($A$4) -> 5 | B9: MEC1804004 | C9: Matehan | D9: =IF(E9="Guarantee",E9&"||"&B9&"||"&C9,B9&"||"&C9) -> MEC1804004||Matehan
A10: =ROW()-ROW($A$4) -> 6 | B10: MEC1804007 | C10: Auto Soldering robot Lether-αII assembly | D10: =IF(E10="Guarantee",E10&"||"&B10&"||"&C10,B10&"||"&C10) -> MEC1804007||Auto Soldering robot Lether-αII assembly
A11: =ROW()-ROW($A$4) -> 7 | B11: MEC1804005 | C11: 2D barcode checking software_MKTC | D11: =IF(E11="Guarantee",E11&"||"&B11&"||"&C11,B11&"||"&C11) -> Guarantee||MEC1804005||2D barcode checking software_MKTC | E11: Guarantee
A12: =ROW()-ROW($A$4) -> 8 | B12: MEC1805001 | C12: 2D barcode Checking_MKVC_2 | D12: =IF(E12="Guarantee",E12&"||"&B12&"||"&C12,B12&"||"&C12) -> Guarantee||MEC1805001||2D barcode Checking_MKVC_2 | E12: Guarantee
A13: =ROW()-ROW($A$4) -> 9 | B13: MEC1805002 | C13: 2D barcode verifying machine | D13: =IF(E13="Guarantee",E13&"||"&B13&"||"&C13,B13&"||"&C13) -> MEC1805002||2D barcode verifying machine
A14: =ROW()-ROW($A$4) -> 10 | B14: MEC1905002 | C14: 3D Printer Trading for VJC | D14: =IF(E14="Guarantee",E14&"||"&B14&"||"&C14,B14&"||"&C14) -> MEC1905002||3D Printer Trading for VJC
A15: =ROW()-ROW($A$4) -> 11 | B15: MEC1810006 | C15: Xe đẩy bo (Cart Trading) | D15: =IF(E15="Guarantee",E15&"||"&B15&"||"&C15,B15&"||"&C15) -> MEC1810006||Xe đẩy bo (Cart Trading)
A16: =ROW()-ROW($A$4) -> 12 | B16: MEC1910006 | C16: Đơn hàng thương mại AUTOCAD (45 licenses) | D16: =IF(E16="Guarantee",E16&"||"&B16&"||"&C16,B16&"||"&C16) -> MEC1910006||Đơn hàng thương mại AUTOCAD (45 licenses) | F16: VG146-191001C
A17: =ROW()-ROW($A$4) -> 13 | B17: MEC1910003 | C17: Đơn hàng thương mại linh kiện tiêu hao cho máy hàn điểm - EMS-190926-01 (Teflon 2) | D17: =IF(E17="Guarantee",E17&"||"&B17&"||"&C17,B17&"||"&C17) -> MEC1910003||Đơn hàng thương mại linh kiện tiêu hao cho máy hàn điểm - EMS-190926-01 (Teflon 2) | F17: VG146-1910001
A18: =ROW()-ROW($A$4) -> 14 | B18: MEC1907005 | C18: HMI JIG gá máy hàn robot model stanley KIFA.RC | D18: =IF(E18="Guarantee",E18&"||"&B18&"||"&C18,B18&"||"&C18) -> MEC1907005||HMI JIG gá máy hàn robot model stanley KIFA.RC | E18: N.V.Quỳnh (cơ)
A19: =ROW()-ROW($A$4) -> 15 | B19: MEC1907006 | C19: Service thêm module tích hợp dữ liệu phân tích hóa chất cho hệ thống SPC | D19: =IF(E19="Guarantee",E19&"||"&B19&"||"&C19,B19&"||"&C19) -> MEC1907006||Service thêm module tích hợp dữ liệu phân tích hóa chất cho hệ thống SPC | E19: A. Phi, Quỳnh 1 | F19: VG41-190701C
A20: =ROW()-ROW($A$4) -> 16 | B20: MEC1908002 | C20: Jig hàn Robot Model HMI Vinfast | D20: =IF(E20="Guarantee",E20&"||"&B20&"||"&C20,B20&"||"&C20) -> MEC1908002||Jig hàn Robot Model HMI Vinfast | E20: N.V.Quỳnh (Cơ) | F20: VG41-19080005
A21: =ROW()-ROW($A$4) -> 17 | B21: MEC1812001 | C21: Số gắn trên Jig mạ | D21: =IF(E21="Guarantee",E21&"||"&B21&"||"&C21,B21&"||"&C21) -> MEC1812001||Số gắn trên Jig mạ | E21: Cart Trading | F21: Done
A22: =ROW()-ROW($A$4) -> 18 | B22: MEC1902005 | C22: Hệ thống chiết xuất dữ liệu của thiết bị phân tích hóa chất tự động_MTE | D22: =IF(E22="Guarantee",E22&"||"&B22&"||"&C22,B22&"||"&C22) -> MEC1902005||Hệ thống chiết xuất dữ liệu của thiết bị phân tích hóa chất tự động_MTE | E22: N.M.Cường, N.T.Phi, V.M.Đức
A23: =ROW()-ROW($A$4) -> 19 | B23: MEC1811001 | C23: Phần mềm SPC cho nhà máy MKVC | D23: =IF(E23="Guarantee",E23&"||"&B23&"||"&C23,B23&"||"&C23) -> MEC1811001||Phần mềm SPC cho nhà máy MKVC | E23: Anh Phi | F23: Done
A24: =ROW()-ROW($A$4) -> 20 | B24: MEC1812004 | C24: Conveyor Long type | D24: =IF(E24="Guarantee",E24&"||"&B24&"||"&C24,B24&"||"&C24) -> MEC1812004||Conveyor Long type | E24: Thành Trần, T.Đ.Hải | F24: Done
A25: =ROW()-ROW($A$4) -> 21 | B25: MEC1812003 | C25: Conveyor aligment | D25: =IF(E25="Guarantee",E25&"||"&B25&"||"&C25,B25&"||"&C25) -> MEC1812003||Conveyor aligment | E25: Thành Trần, T.Đ.Hải | F25: Done
A26: =ROW()-ROW($A$4) -> 22 | B26: MEC1812002 | C26: Conveyor | D26: =IF(E26="Guarantee",E26&"||"&B26&"||"&C26,B26&"||"&C26) -> MEC1812002||Conveyor | E26: Thành Trần, T.Đ.Hải (Short Conveyor) | F26: Done
A27: =ROW()-ROW($A$4) -> 23 | B27: MEC1911035 | C27: Case of gateway | D27: =IF(E27="Guarantee",E27&"||"&B27&"||"&C27,B27&"||"&C27) -> MEC1911035||Case of gateway | E27: Cường.NM | F27: VG146-19120001
A28: =ROW()-ROW($A$4) -> 24 | B28: MEC1911039 | C28: Bảo trì hệ thống tổng đài điện thoại | D28: =IF(E28="Guarantee",E28&"||"&B28&"||"&C28,B28&"||"&C28) -> MEC1911039||Bảo trì hệ thống tổng đài điện thoại | F28: VG146-191201C
A29: =ROW()-ROW($A$4) -> 25 | B29: MEC1911043 | C29: Đèn LED Tube UV cut<500 nm, công suất 20W, quang thông 1100Lm | D29: =IF(E29="Guarantee",E29&"||"&B29&"||"&C29,B29&"||"&C29) -> MEC1911043||Đèn LED Tube UV cut<500 nm, công suất 20W, quang thông 1100Lm | F29: VG146-19122001
A30: =ROW()-ROW($A$4) -> 26 | B30: MEC1810003 | C30: LaserMaking | D30: =IF(E30="Guarantee",E30&"||"&B30&"||"&C30,B30&"||"&C30) -> MEC1810003||LaserMaking
A31: =ROW()-ROW($A$4) -> 27 | B31: MEC1807001 | C31: Dự án thiết kế thiết bị chuyển mạch video | D31: =IF(E31="Guarantee",E31&"||"&B31&"||"&C31,B31&"||"&C31) -> MEC1807001||Dự án thiết kế thiết bị chuyển mạch video
A32: =ROW()-ROW($A$4) -> 28 | B32: MEC1910007 | C32: Matehan_Fact2_CopperPlate_LoadingMachine | D32: =IF(E32="Guarantee",E32&"||"&B32&"||"&C32,B32&"||"&C32) -> MEC1910007||Matehan_Fact2_CopperPlate_LoadingMachine
A33: =ROW()-ROW($A$4) -> 29 | B33: MEC1907004 | C33: Xe Hrack | D33: =IF(E33="Guarantee",E33&"||"&B33&"||"&C33,B33&"||"&C33) -> MEC1907004||Xe Hrack | E33: T.T.Anh
A34: =ROW()-ROW($A$4) -> 30 | B34: IOT1 | C34: IoT Meiko Techno | D34: =IF(E34="Guarantee",E34&"||"&B34&"||"&C34,B34&"||"&C34) -> IOT1||IoT Meiko Techno | E34: N.M.Cường
A35: =ROW()-ROW($A$4) -> 31 | B35: MEC1903002 | C35: Solder Jig | D35: =IF(E35="Guarantee",E35&"||"&B35&"||"&C35,B35&"||"&C35) -> MEC1903002||Solder Jig | E35: N.V.Quỳnh
A36: =ROW()-ROW($A$4) -> 32 | B36: MEC1901001 | C36: Soldering robot 5 set | D36: =IF(E36="Guarantee",E36&"||"&B36&"||"&C36,B36&"||"&C36) -> MEC1901001||Soldering robot 5 set | E36: N.M.Tiến
A37: =ROW()-ROW($A$4) -> 33 | B37: MEC1911006 | C37: Hệ thống chiết xuất dữ liệu của thiết bị phân tích hóa chất tự động - Lần 2_15_MKAC | D37: =IF(E37="Guarantee",E37&"||"&B37&"||"&C37,B37&"||"&C37) -> MEC1911006||Hệ thống chiết xuất dữ liệu của thiết bị phân tích hóa chất tự động - Lần 2_15_MKAC | E37: Anh.Cường R&D | F37: VG146-19110002 | G37: Chưa có PO, chưa hoàn thành
A38: =ROW()-ROW($A$4) -> 34 | B38: MEC1911007 | C38: Phần mềm kết nối dữ liệu 2 máy đo lên hệ thống SPC tại FPC_40_Lần 1 | D38: =IF(E38="Guarantee",E38&"||"&B38&"||"&C38,B38&"||"&C38) -> MEC1911007||Phần mềm kết nối dữ liệu 2 máy đo lên hệ thống SPC tại FPC_40_Lần 1 | E38: Anh Phi | F38: VG146-191101C | G38: Chưa có PO, chưa có thông tin làm tiếp
A39: =ROW()-ROW($A$4) -> 35 | B39: MEC1911009 | C39: Phần mềm kết nối dữ liệu 2 máy đo lên hệ thống SPC tại FPC_40_Lần 2 | D39: =IF(E39="Guarantee",E39&"||"&B39&"||"&C39,B39&"||"&C39) -> MEC1911009||Phần mềm kết nối dữ liệu 2 máy đo lên hệ thống SPC tại FPC_40_Lần 2 | E39: Anh Phi | F39: VG146-191102C
A40: =ROW()-ROW($A$4) -> 36 | B40: AM100850 | C40: JIG616 cho dây chuyền mạ VCP & Filled L1230*W780mm. | D40: =IF(E40="Guarantee",E40&"||"&B40&"||"&C40,B40&"||"&C40) -> AM100850||JIG616 cho dây chuyền mạ VCP & Filled L1230*W780mm. | E40: Mr.Nguyễn tuấn, chu tuấn, giang | F40: Chưa có PO => Hủy do k đảm bảo chất lượng
A41: =ROW()-ROW($A$4) -> 37 | B41: AM100851 | C41: JIG612 cho dây chuyền mạ VCP & Filled L1230*W820mm. | D41: =IF(E41="Guarantee",E41&"||"&B41&"||"&C41,B41&"||"&C41) -> AM100851||JIG612 cho dây chuyền mạ VCP & Filled L1230*W820mm. | E41: Mr.Nguyễn tuấn, chu tuấn, giang | F41: Chưa có PO => Hủy do k đảm bảo chất lượng
A42: =ROW()-ROW($A$4) -> 38 | B42: AM100852 | C42: JIG608 cho dây chuyền mạ VCP & Filled L1230*W860mm. | D42: =IF(E42="Guarantee",E42&"||"&B42&"||"&C42,B42&"||"&C42) -> AM100852||JIG608 cho dây chuyền mạ VCP & Filled L1230*W860mm. | E42: Mr.Nguyễn tuấn, chu tuấn, giang | F42: Chưa có PO => Hủy do k đảm bảo chất lượng | G42: Bản vẽ của Chu Tuấn
...

Sheet Hướng dẫn_KT
A2: 1 | B2: Hàng ngày khi có nhân sự mới phải gửi hướng dẫn: theo sheet: ''Hướng dẫn điền timesheet"
A4: 2 | B4: Các nhân sự thuộc các phòng ban sau phải điền timesheet: AUTO, IOT, ICT, AGV, SALE_SERVICE
B5: Thêm nhân sự mới : Vào Sheet DMNV tương ứng với tháng trong file TS_tháng
A21: 3 | B21: Điền các thông tin cần thiết: những cột chữ mờ thì kéo công thức
A35: 4 | B35: Check sheet TS_tháng xem đã hiện tên chưa, nếu chưa có thì kiểm tra lại vùng, insert thêm dòng
B36: Share link cho email ( nếu là email cá nhân, k phải mail công ty)
B37: Phân quyền nhân sự theo từng mail : Bôi đen vùng cần phân quyền=> chọn data=> protect sheet and range => chọn edit=> mail được phân quyền=> bấm lưu
B38: Lưu tên vùng được phân quyền theo nội dung: STT_ID_Tên_Bộ phận
A40: 5 | B40: Các nội dung về điền dự án như thế nào, cảnh báo khi điền sai theo sheet: hướng dẫn điền timesheet
B41: Hàng ngày khi có nhân sự mới phải gửi hướng dẫn
A43: 6 | B43: Cuối tháng check sheet summary
B44: Sheet này là tổng hợp time điền các dự án theo từng nhân sự
B45: Kéo lại công thức hàng tháng
B46: Check cột D phần chênh lệch: thời gian câu từ sheet TS_tháng có đúng k ?Nếu lệch check chi tiết
B47: Check dòng thứ 4 từng nhân sự xem có cảnh báo điền sai k?
B48: Check lại tổng time cột C4 vs tổng thời gian của sheet TS_tháng
A55: Tạo phân quyền điền timesheet
A56: B1 | B56: Tại sheet DMNV
B57: Điền thông tin nhân viên vào sheet DMNV
B58: Lưu ý: Chỉ cần điền tên và email phân quyền, phần vùng phân quyền đang tạo công thức chỉ việc copy từ dòng trên xuống
A59: B2 | B59: Tại sheet Timesheet
B60: Copy thêm vùng dữ liệu cần tạo thêm
B61: Lưu ý: Công thức đã tạo sẵn để chỉ chạy theo STT ở sheet DMNV, không cần điền tay tên NSự ở sheet này
A62: B3 | B62: Tại sheet Timesheet
B63: Click "Set permission" để tiến hành phân quyền lại (nếu có thay đổi STT ở DMNV)
A65: Note: | B65: Đối với các nhân sự đã nghỉ việc, có thể xóa dòng thông tin của NS đó ở sheet DMNV và tiến hành Set permission lại ở các sheet Timesheet

Sheet KT Check
A1: DANH SÁCH DỰ ÁN TỒN NC 154 | D1: DANH SÁCH DỰ ÁN BÁN TRONG THÁNG | I1: DANH SÁCH DỰ ÁN PHÁT SINH TRONG THÁNG
A2: Đến tháng | B2: 45809 | D2: Tháng | E2: =EDATE(B2,1) -> 45839 | I2: Tháng | J2: =E2 -> 45839
A3: Lọc NC<>0, Tồn <>0 | D3: Tên sheet TH | E3: ="Summary_"&TEXT(E2,"MMYY") -> Summary_0725
A4: Mã sản phẩm | B4: Tên sản phẩm | D4: Mã sản phẩm | E4: Tên sản phẩm | F4: Tồn 154 | G4: Số giờ | I4: Mã sản phẩm | J4: Tên sản phẩm | K4: Số giờ | L4: Bán | M4: Tồn
A5: 55MEC2012002 | D5: 55MEC2409006 | E5: MEC2409006||Phần mềm LDI/ Laser cho máy khắc laser Vũ Hán | F5: =IF(IFERROR(VLOOKUP($D5,$A$5:$A$6000,1,FALSE),"x")<>"x","Y",".") -> . | G5: =SUMIFS(INDIRECT(""&$E$3&"!"&"$C$6"):INDIRECT(""&$E$3&"!"&"$C$20000"),INDIRECT(""&$E$3&"!"&"$B$6"):INDIRECT(""&$E$3&"!"&"$B$20000"),$D5) -> #REF! | I5: Annual Leave | J5: Annual Leave | K5: =SUMIFS(INDIRECT(""&$E$3&"!"&"$C$6"):INDIRECT(""&$E$3&"!"&"$C$2000"),INDIRECT(""&$E$3&"!"&"$B$6"):INDIRECT(""&$E$3&"!"&"$B$2000"),$I5) -> #REF! | L5: =IFERROR(VLOOKUP($I5,$D$5:$D$100,1,FALSE),".") -> . | M5: =IFERROR(VLOOKUP($I5,$A$5:$A$200,1,FALSE),".") -> .
A6: 55MEC2004003 | D6: 55MEC2407017_B | E6: Phần mềm xuất file cXML chỉ chứa mã lot + số lượng pcs | F6: =IF(IFERROR(VLOOKUP($D6,$A$5:$A$6000,1,FALSE),"x")<>"x","Y",".") -> . | G6: =SUMIFS(INDIRECT(""&$E$3&"!"&"$C$6"):INDIRECT(""&$E$3&"!"&"$C$20000"),INDIRECT(""&$E$3&"!"&"$B$6"):INDIRECT(""&$E$3&"!"&"$B$20000"),$D6) -> #REF! | I6: Other | J6: Other | K6: =SUMIFS(INDIRECT(""&$E$3&"!"&"$C$6"):INDIRECT(""&$E$3&"!"&"$C$2000"),INDIRECT(""&$E$3&"!"&"$B$6"):INDIRECT(""&$E$3&"!"&"$B$2000"),$I6) -> #REF! | L6: =IFERROR(VLOOKUP($I6,$D$5:$D$100,1,FALSE),".") -> . | M6: =IFERROR(VLOOKUP($I6,$A$5:$A$200,1,FALSE),".") -> .
A7: 55MEC2009011 | D7: 55MEC2407017_A | E7: Phần mềm đọc mã 2D barcode trên sheet và xuất file cXML chứa mã lot + mã pcs | F7: =IF(IFERROR(VLOOKUP($D7,$A$5:$A$6000,1,FALSE),"x")<>"x","Y",".") -> . | G7: =SUMIFS(INDIRECT(""&$E$3&"!"&"$C$6"):INDIRECT(""&$E$3&"!"&"$C$20000"),INDIRECT(""&$E$3&"!"&"$B$6"):INDIRECT(""&$E$3&"!"&"$B$20000"),$D7) -> #REF! | I7: QLC | J7: QLC | K7: =SUMIFS(INDIRECT(""&$E$3&"!"&"$C$6"):INDIRECT(""&$E$3&"!"&"$C$2000"),INDIRECT(""&$E$3&"!"&"$B$6"):INDIRECT(""&$E$3&"!"&"$B$2000"),$I7) -> #REF! | L7: =IFERROR(VLOOKUP($I7,$D$5:$D$100,1,FALSE),".") -> . | M7: =IFERROR(VLOOKUP($I7,$A$5:$A$200,1,FALSE),".") -> .
A8: 55MEC2009010 | D8: 55MEC2403061 | E8: MEC2403061 Máy nhận bo V rack TYPE 4 Line Rửa nước sau ép lớp | F8: =IF(IFERROR(VLOOKUP($D8,$A$5:$A$6000,1,FALSE),"x")<>"x","Y",".") -> Y | G8: =SUMIFS(INDIRECT(""&$E$3&"!"&"$C$6"):INDIRECT(""&$E$3&"!"&"$C$20000"),INDIRECT(""&$E$3&"!"&"$B$6"):INDIRECT(""&$E$3&"!"&"$B$20000"),$D8) -> #REF! | I8: 55MEC2201011 | J8: MEC2201011||Carrier device (Load/Unload) for Laser VIA (4 Axis) for Ishinomaki #1 | K8: =SUMIFS(INDIRECT(""&$E$3&"!"&"$C$6"):INDIRECT(""&$E$3&"!"&"$C$2000"),INDIRECT(""&$E$3&"!"&"$B$6"):INDIRECT(""&$E$3&"!"&"$B$2000"),$I8) -> #REF! | L8: =IFERROR(VLOOKUP($I8,$D$5:$D$100,1,FALSE),".") -> . | M8: =IFERROR(VLOOKUP($I8,$A$5:$A$200,1,FALSE),".") -> 55MEC2201011
A9: 55MEC2107001 | D9: 55MEC2403062 | E9: Máy đưa bo Vrack Line Rửa nước sau ép lớp Fact.3 | F9: =IF(IFERROR(VLOOKUP($D9,$A$5:$A$6000,1,FALSE),"x")<>"x","Y",".") -> Y | G9: =SUMIFS(INDIRECT(""&$E$3&"!"&"$C$6"):INDIRECT(""&$E$3&"!"&"$C$20000"),INDIRECT(""&$E$3&"!"&"$B$6"):INDIRECT(""&$E$3&"!"&"$B$20000"),$D9) -> #REF! | I9: 55MEC2205009 | J9: MEC2205009||2V-rack 1H-rack Unloader (MKUL-DR1-7171IC) | K9: =SUMIFS(INDIRECT(""&$E$3&"!"&"$C$6"):INDIRECT(""&$E$3&"!"&"$C$2000"),INDIRECT(""&$E$3&"!"&"$B$6"):INDIRECT(""&$E$3&"!"&"$B$2000"),$I9) -> #REF! | L9: =IFERROR(VLOOKUP($I9,$D$5:$D$100,1,FALSE),".") -> . | M9: =IFERROR(VLOOKUP($I9,$A$5:$A$200,1,FALSE),".") -> .
A10: 55MEC2109013 | D10: 55MEC2403071 | E10: MEC2403071||Máy đưa bo V rack TYPE 4 Line Glass Etching MEC2403071 | F10: =IF(IFERROR(VLOOKUP($D10,$A$5:$A$6000,1,FALSE),"x")<>"x","Y",".") -> Y | G10: =SUMIFS(INDIRECT(""&$E$3&"!"&"$C$6"):INDIRECT(""&$E$3&"!"&"$C$20000"),INDIRECT(""&$E$3&"!"&"$B$6"):INDIRECT(""&$E$3&"!"&"$B$20000"),$D10) -> #REF! | I10: 55MEC2205029 | J10: MEC2205029||2V-rack 1H-rack Unloader (MKUL-DR1-7171IC) | K10: =SUMIFS(INDIRECT(""&$E$3&"!"&"$C$6"):INDIRECT(""&$E$3&"!"&"$C$2000"),INDIRECT(""&$E$3&"!"&"$B$6"):INDIRECT(""&$E$3&"!"&"$B$2000"),$I10) -> #REF! | L10: =IFERROR(VLOOKUP($I10,$D$5:$D$100,1,FALSE),".") -> . | M10: =IFERROR(VLOOKUP($I10,$A$5:$A$200,1,FALSE),".") -> .
A11: 55MEC2109024 | D11: 55MEC2403073 | E11: Máy đưa bo V rack TYPE 4 Line Glass Etching MEC2403073 | F11: =IF(IFERROR(VLOOKUP($D11,$A$5:$A$6000,1,FALSE),"x")<>"x","Y",".") -> Y | G11: =SUMIFS(INDIRECT(""&$E$3&"!"&"$C$6"):INDIRECT(""&$E$3&"!"&"$C$20000"),INDIRECT(""&$E$3&"!"&"$B$6"):INDIRECT(""&$E$3&"!"&"$B$20000"),$D11) -> #REF! | I11: 55MEC2206012 | J11: MEC2206012||第3 ２FのVCP- XVIA #2 投入機 BOX 式 Máy đưa bo PKG BOX line VCP-XVIA #2 | K11: =SUMIFS(INDIRECT(""&$E$3&"!"&"$C$6"):INDIRECT(""&$E$3&"!"&"$C$2000"),INDIRECT(""&$E$3&"!"&"$B$6"):INDIRECT(""&$E$3&"!"&"$B$2000"),$I11) -> #REF! | L11: =IFERROR(VLOOKUP($I11,$D$5:$D$100,1,FALSE),".") -> . | M11: =IFERROR(VLOOKUP($I11,$A$5:$A$200,1,FALSE),".") -> .
A12: 55MEC2111030 | D12: 55MEC2412001 | E12: MEC2412001||Dịch vụ sửa chữa máy đưa bo line in sơn lấp lỗ #1 | F12: =IF(IFERROR(VLOOKUP($D12,$A$5:$A$6000,1,FALSE),"x")<>"x","Y",".") -> Y | G12: V | I12: 55MEC2208020 | J12: MEC2208020||プラズマ処理 投入機（マガジン式） Máy đưa bo line Xử lý Plasma (Magazine) | K12: =SUMIFS(INDIRECT(""&$E$3&"!"&"$C$6"):INDIRECT(""&$E$3&"!"&"$C$2000"),INDIRECT(""&$E$3&"!"&"$B$6"):INDIRECT(""&$E$3&"!"&"$B$2000"),$I12) -> #REF! | L12: =IFERROR(VLOOKUP($I12,$D$5:$D$100,1,FALSE),".") -> . | M12: =IFERROR(VLOOKUP($I12,$A$5:$A$200,1,FALSE),".") -> .
A13: 55MEC2112010 | D13: 55MEC2412002 | E13: Dịch vụ sửa robot 6 trục máy đưa bo line TXL#3 TM NM3 | F13: =IF(IFERROR(VLOOKUP($D13,$A$5:$A$6000,1,FALSE),"x")<>"x","Y",".") -> . | G13: =SUMIFS(INDIRECT(""&$E$3&"!"&"$C$6"):INDIRECT(""&$E$3&"!"&"$C$20000"),INDIRECT(""&$E$3&"!"&"$B$6"):INDIRECT(""&$E$3&"!"&"$B$20000"),$D13) -> #REF! | I13: 55MEC2211007 | J13: MEC2211007||Phát triển sản phẩm IoT Meiko Automation (Giai đoạn 3 - MKVC) | K13: =SUMIFS(INDIRECT(""&$E$3&"!"&"$C$6"):INDIRECT(""&$E$3&"!"&"$C$2000"),INDIRECT(""&$E$3&"!"&"$B$6"):INDIRECT(""&$E$3&"!"&"$B$2000"),$I13) -> #REF! | L13: =IFERROR(VLOOKUP($I13,$D$5:$D$100,1,FALSE),".") -> . | M13: =IFERROR(VLOOKUP($I13,$A$5:$A$200,1,FALSE),".") -> 55MEC2211007
A14: 55MEC2112011 | D14: 55MEC2401005 | E14: MEC2401005||Lắp đặt máy cho nhà máy Tendou giai đoạn 2/ Installation fees of matehan machine at Tendo factory | F14: =IF(IFERROR(VLOOKUP($D14,$A$5:$A$6000,1,FALSE),"x")<>"x","Y",".") -> Y | G14: =SUMIFS(INDIRECT(""&$E$3&"!"&"$C$6"):INDIRECT(""&$E$3&"!"&"$C$20000"),INDIRECT(""&$E$3&"!"&"$B$6"):INDIRECT(""&$E$3&"!"&"$B$20000"),$D14) -> #REF! | I14: 55MEC2304014 | J14: MEC2304014||Dự án cải tiến AGF cho nhà máy Canon Thăng Long (xe đầu tiên) | K14: =SUMIFS(INDIRECT(""&$E$3&"!"&"$C$6"):INDIRECT(""&$E$3&"!"&"$C$2000"),INDIRECT(""&$E$3&"!"&"$B$6"):INDIRECT(""&$E$3&"!"&"$B$2000"),$I14) -> #REF! | L14: =IFERROR(VLOOKUP($I14,$D$5:$D$100,1,FALSE),".") -> . | M14: =IFERROR(VLOOKUP($I14,$A$5:$A$200,1,FALSE),".") -> .
A15: 55MEC2112012 | D15: 55MEC2308005 | E15: Services Hạ tầng nhà máy MKVC (tháng 7/2024 - tháng 12/2024) | F15: =IF(IFERROR(VLOOKUP($D15,$A$5:$A$6000,1,FALSE),"x")<>"x","Y",".") -> . | G15: =SUMIFS(INDIRECT(""&$E$3&"!"&"$C$6"):INDIRECT(""&$E$3&"!"&"$C$20000"),INDIRECT(""&$E$3&"!"&"$B$6"):INDIRECT(""&$E$3&"!"&"$B$20000"),$D15) -> #REF! | I15: 55MEC2305009 | J15: MEC2305009||Máy nhận bo line in chữ bằng tay- Semi Cure 手動印刷～セミキュア受取機 | K15: =SUMIFS(INDIRECT(""&$E$3&"!"&"$C$6"):INDIRECT(""&$E$3&"!"&"$C$2000"),INDIRECT(""&$E$3&"!"&"$B$6"):INDIRECT(""&$E$3&"!"&"$B$2000"),$I15) -> #REF! | L15: =IFERROR(VLOOKUP($I15,$D$5:$D$100,1,FALSE),".") -> . | M15: =IFERROR(VLOOKUP($I15,$A$5:$A$200,1,FALSE),".") -> .
A16: 55MEC2112013 | D16: 55MEC2308006 | E16: Services Hạ tầng nhà máy MKTC (tháng 7/2024 - tháng 12/2024) | F16: =IF(IFERROR(VLOOKUP($D16,$A$5:$A$6000,1,FALSE),"x")<>"x","Y",".") -> . | G16: =SUMIFS(INDIRECT(""&$E$3&"!"&"$C$6"):INDIRECT(""&$E$3&"!"&"$C$20000"),INDIRECT(""&$E$3&"!"&"$B$6"):INDIRECT(""&$E$3&"!"&"$B$20000"),$D16) -> #REF! | I16: 55MEC2305013 | J16: MEC2305013||CZ処理 投入機（マガジン式） Máy đưa bo line CZ (Magazine) | K16: =SUMIFS(INDIRECT(""&$E$3&"!"&"$C$6"):INDIRECT(""&$E$3&"!"&"$C$2000"),INDIRECT(""&$E$3&"!"&"$B$6"):INDIRECT(""&$E$3&"!"&"$B$2000"),$I16) -> #REF! | L16: =IFERROR(VLOOKUP($I16,$D$5:$D$100,1,FALSE),".") -> . | M16: =IFERROR(VLOOKUP($I16,$A$5:$A$200,1,FALSE),".") -> .
A17: 55MEC2112014 | D17: 55MEC2407033 | E17: MEC2407033||Sửa chữa máy VCP#9_240702 | F17: =IF(IFERROR(VLOOKUP($D17,$A$5:$A$6000,1,FALSE),"x")<>"x","Y",".") -> Y | G17: =SUMIFS(INDIRECT(""&$E$3&"!"&"$C$6"):INDIRECT(""&$E$3&"!"&"$C$20000"),INDIRECT(""&$E$3&"!"&"$B$6"):INDIRECT(""&$E$3&"!"&"$B$20000"),$D17) -> #REF! | I17: 55MEC2305014 | J17: MEC2305014||ABFラミネート 受取機（マガジン式） Máy nhận bo line Dán màng ABF (Magazine) | K17: =SUMIFS(INDIRECT(""&$E$3&"!"&"$C$6"):INDIRECT(""&$E$3&"!"&"$C$2000"),INDIRECT(""&$E$3&"!"&"$B$6"):INDIRECT(""&$E$3&"!"&"$B$2000"),$I17) -> #REF! | L17: =IFERROR(VLOOKUP($I17,$D$5:$D$100,1,FALSE),".") -> . | M17: =IFERROR(VLOOKUP($I17,$A$5:$A$200,1,FALSE),".") -> .
A18: 55MEC2112015 | D18: 55MEC2407032 | E18: MEC2407032||Sửa chữa máy VCP#9 | F18: =IF(IFERROR(VLOOKUP($D18,$A$5:$A$6000,1,FALSE),"x")<>"x","Y",".") -> Y | G18: =SUMIFS(INDIRECT(""&$E$3&"!"&"$C$6"):INDIRECT(""&$E$3&"!"&"$C$20000"),INDIRECT(""&$E$3&"!"&"$B$6"):INDIRECT(""&$E$3&"!"&"$B$20000"),$D18) -> #REF! | I18: 55MEC2305017 | J18: MEC2305017||SR印刷→セミキュア 投入機（マガジン式） Máy đưa bo line In SR --> bán cố hóa (Magazine) | K18: =SUMIFS(INDIRECT(""&$E$3&"!"&"$C$6"):INDIRECT(""&$E$3&"!"&"$C$2000"),INDIRECT(""&$E$3&"!"&"$B$6"):INDIRECT(""&$E$3&"!"&"$B$2000"),$I18) -> #REF! | L18: =IFERROR(VLOOKUP($I18,$D$5:$D$100,1,FALSE),".") -> . | M18: =IFERROR(VLOOKUP($I18,$A$5:$A$200,1,FALSE),".") -> .
A19: 55MEC2112016 | D19: 55MEC2411027 | E19: MEC2411027||Dịch vụ làm chương trình khắc và kiểm tra 2D barcode hàng Z 8L mã 2369-1012 và 2369-2106 | F19: =IF(IFERROR(VLOOKUP($D19,$A$5:$A$6000,1,FALSE),"x")<>"x","Y",".") -> Y | G19: =SUMIFS(INDIRECT(""&$E$3&"!"&"$C$6"):INDIRECT(""&$E$3&"!"&"$C$20000"),INDIRECT(""&$E$3&"!"&"$B$6"):INDIRECT(""&$E$3&"!"&"$B$20000"),$D19) -> #REF! | I19: 55MEC2305018 | J19: MEC2305018||SR印刷 受取機（マガジン式） Máy nhận bo line SR (Magazine) | K19: =SUMIFS(INDIRECT(""&$E$3&"!"&"$C$6"):INDIRECT(""&$E$3&"!"&"$C$2000"),INDIRECT(""&$E$3&"!"&"$B$6"):INDIRECT(""&$E$3&"!"&"$B$2000"),$I19) -> #REF! | L19: =IFERROR(VLOOKUP($I19,$D$5:$D$100,1,FALSE),".") -> . | M19: =IFERROR(VLOOKUP($I19,$A$5:$A$200,1,FALSE),".") -> .
A20: 55MEC2201001 | D20: 55MEC2411018 | E20: Dịch vụ bảo dưỡng hệ thống PCCC MKVC | F20: =IF(IFERROR(VLOOKUP($D20,$A$5:$A$6000,1,FALSE),"x")<>"x","Y",".") -> . | G20: =SUMIFS(INDIRECT(""&$E$3&"!"&"$C$6"):INDIRECT(""&$E$3&"!"&"$C$20000"),INDIRECT(""&$E$3&"!"&"$B$6"):INDIRECT(""&$E$3&"!"&"$B$20000"),$D20) -> #REF! | I20: 55MEC2305019 | J20: MEC2305019||UV照射 受取機（マガジン式） Máy nhận bo line chiếu UV (Magazine) | K20: =SUMIFS(INDIRECT(""&$E$3&"!"&"$C$6"):INDIRECT(""&$E$3&"!"&"$C$2000"),INDIRECT(""&$E$3&"!"&"$B$6"):INDIRECT(""&$E$3&"!"&"$B$2000"),$I20) -> #REF! | L20: =IFERROR(VLOOKUP($I20,$D$5:$D$100,1,FALSE),".") -> . | M20: =IFERROR(VLOOKUP($I20,$A$5:$A$200,1,FALSE),".") -> .
A21: 55MEC2201002 | F21: =IF(IFERROR(VLOOKUP($D21,$A$5:$A$6000,1,FALSE),"x")<>"x","Y",".") -> . | G21: =SUMIFS(INDIRECT(""&$E$3&"!"&"$C$6"):INDIRECT(""&$E$3&"!"&"$C$20000"),INDIRECT(""&$E$3&"!"&"$B$6"):INDIRECT(""&$E$3&"!"&"$B$20000"),$D21) -> #REF! | I21: 55MEC2305020 | J21: MEC2305020||ウェットブラスト→酸洗 投入機（マガジン式） Máy đưa bo line Wet blast -> Rửa axit (Magazine) | K21: =SUMIFS(INDIRECT(""&$E$3&"!"&"$C$6"):INDIRECT(""&$E$3&"!"&"$C$2000"),INDIRECT(""&$E$3&"!"&"$B$6"):INDIRECT(""&$E$3&"!"&"$B$2000"),$I21) -> #REF! | L21: =IFERROR(VLOOKUP($I21,$D$5:$D$100,1,FALSE),".") -> . | M21: =IFERROR(VLOOKUP($I21,$A$5:$A$200,1,FALSE),".") -> .
A22: 55MEC2201011 | D22: sửa lại mã PCCC vì là mua hàng thương mại | F22: =IF(IFERROR(VLOOKUP($D22,$A$5:$A$6000,1,FALSE),"x")<>"x","Y",".") -> . | G22: =SUMIFS(INDIRECT(""&$E$3&"!"&"$C$6"):INDIRECT(""&$E$3&"!"&"$C$20000"),INDIRECT(""&$E$3&"!"&"$B$6"):INDIRECT(""&$E$3&"!"&"$B$20000"),$D22) -> #REF! | I22: 55MEC2308005 | J22: MEC2308005||Services Hạ tầng nhà máy MKVC (tháng 7/2024 - tháng 12/2024) | K22: =SUMIFS(INDIRECT(""&$E$3&"!"&"$C$6"):INDIRECT(""&$E$3&"!"&"$C$2000"),INDIRECT(""&$E$3&"!"&"$B$6"):INDIRECT(""&$E$3&"!"&"$B$2000"),$I22) -> #REF! | L22: =IFERROR(VLOOKUP($I22,$D$5:$D$100,1,FALSE),".") -> 55MEC2308005 | M22: =IFERROR(VLOOKUP($I22,$A$5:$A$200,1,FALSE),".") -> .
A23: 55MEC2201013 | D23: mã MEC2407017_B và 55MEC2407017_A | F23: =IF(IFERROR(VLOOKUP($D23,$A$5:$A$6000,1,FALSE),"x")<>"x","Y",".") -> . | G23: =SUMIFS(INDIRECT(""&$E$3&"!"&"$C$6"):INDIRECT(""&$E$3&"!"&"$C$20000"),INDIRECT(""&$E$3&"!"&"$B$6"):INDIRECT(""&$E$3&"!"&"$B$20000"),$D23) -> #REF! | I23: 55MEC2308006 | J23: MEC2308006||Services Hạ tầng nhà máy MKTC (tháng 7/2024 - tháng 12/2024) | K23: =SUMIFS(INDIRECT(""&$E$3&"!"&"$C$6"):INDIRECT(""&$E$3&"!"&"$C$2000"),INDIRECT(""&$E$3&"!"&"$B$6"):INDIRECT(""&$E$3&"!"&"$B$2000"),$I23) -> #REF! | L23: =IFERROR(VLOOKUP($I23,$D$5:$D$100,1,FALSE),".") -> 55MEC2308006 | M23: =IFERROR(VLOOKUP($I23,$A$5:$A$200,1,FALSE),".") -> .
A24: 55MEC2203003 | F24: =IF(IFERROR(VLOOKUP($D24,$A$5:$A$6000,1,FALSE),"x")<>"x","Y",".") -> . | G24: =SUMIFS(INDIRECT(""&$E$3&"!"&"$C$6"):INDIRECT(""&$E$3&"!"&"$C$20000"),INDIRECT(""&$E$3&"!"&"$B$6"):INDIRECT(""&$E$3&"!"&"$B$20000"),$D24) -> #REF! | I24: 55MEC2309021 | J24: MEC2309021||Máy đưa bo (Loader) V rack TYPE 3 line Mài lỗ （３F SR） 穴理研磨 （３F SR） 投入機（Vラック） | K24: =SUMIFS(INDIRECT(""&$E$3&"!"&"$C$6"):INDIRECT(""&$E$3&"!"&"$C$2000"),INDIRECT(""&$E$3&"!"&"$B$6"):INDIRECT(""&$E$3&"!"&"$B$2000"),$I24) -> #REF! | L24: =IFERROR(VLOOKUP($I24,$D$5:$D$100,1,FALSE),".") -> . | M24: =IFERROR(VLOOKUP($I24,$A$5:$A$200,1,FALSE),".") -> .
A25: 55MEC2203004 | F25: =IF(IFERROR(VLOOKUP($D25,$A$5:$A$6000,1,FALSE),"x")<>"x","Y",".") -> . | G25: =SUMIFS(INDIRECT(""&$E$3&"!"&"$C$6"):INDIRECT(""&$E$3&"!"&"$C$20000"),INDIRECT(""&$E$3&"!"&"$B$6"):INDIRECT(""&$E$3&"!"&"$B$20000"),$D25) -> #REF! | I25: 55MEC2309024 | J25: MEC2309024||Máy đưa bo (Loader) L rack 投入機（Lラック） | K25: =SUMIFS(INDIRECT(""&$E$3&"!"&"$C$6"):INDIRECT(""&$E$3&"!"&"$C$2000"),INDIRECT(""&$E$3&"!"&"$B$6"):INDIRECT(""&$E$3&"!"&"$B$2000"),$I25) -> #REF! | L25: =IFERROR(VLOOKUP($I25,$D$5:$D$100,1,FALSE),".") -> . | M25: =IFERROR(VLOOKUP($I25,$A$5:$A$200,1,FALSE),".") -> .
A26: 55MEC2204003 | F26: =IF(IFERROR(VLOOKUP($D26,$A$5:$A$6000,1,FALSE),"x")<>"x","Y",".") -> . | G26: =SUMIFS(INDIRECT(""&$E$3&"!"&"$C$6"):INDIRECT(""&$E$3&"!"&"$C$20000"),INDIRECT(""&$E$3&"!"&"$B$6"):INDIRECT(""&$E$3&"!"&"$B$20000"),$D26) -> #REF! | I26: 55MEC2310016 | J26: MEC2310016|| Máy Unloading Magazine dạng sheet | K26: =SUMIFS(INDIRECT(""&$E$3&"!"&"$C$6"):INDIRECT(""&$E$3&"!"&"$C$2000"),INDIRECT(""&$E$3&"!"&"$B$6"):INDIRECT(""&$E$3&"!"&"$B$2000"),$I26) -> #REF! | L26: =IFERROR(VLOOKUP($I26,$D$5:$D$100,1,FALSE),".") -> . | M26: =IFERROR(VLOOKUP($I26,$A$5:$A$200,1,FALSE),".") -> 55MEC2310016
A27: 55MEC2207011 | F27: =IF(IFERROR(VLOOKUP($D27,$A$5:$A$6000,1,FALSE),"x")<>"x","Y",".") -> . | G27: =SUMIFS(INDIRECT(""&$E$3&"!"&"$C$6"):INDIRECT(""&$E$3&"!"&"$C$20000"),INDIRECT(""&$E$3&"!"&"$B$6"):INDIRECT(""&$E$3&"!"&"$B$20000"),$D27) -> #REF! | I27: 55MEC2311012 | J27: MEC2311012||Máy khắc 2D code bo mạch, tự động Load và Unload | K27: =SUMIFS(INDIRECT(""&$E$3&"!"&"$C$6"):INDIRECT(""&$E$3&"!"&"$C$2000"),INDIRECT(""&$E$3&"!"&"$B$6"):INDIRECT(""&$E$3&"!"&"$B$2000"),$I27) -> #REF! | L27: =IFERROR(VLOOKUP($I27,$D$5:$D$100,1,FALSE),".") -> . | M27: =IFERROR(VLOOKUP($I27,$A$5:$A$200,1,FALSE),".") -> .
A28: 55MEC2209009 | F28: =IF(IFERROR(VLOOKUP($D28,$A$5:$A$6000,1,FALSE),"x")<>"x","Y",".") -> . | G28: =SUMIFS(INDIRECT(""&$E$3&"!"&"$C$6"):INDIRECT(""&$E$3&"!"&"$C$20000"),INDIRECT(""&$E$3&"!"&"$B$6"):INDIRECT(""&$E$3&"!"&"$B$20000"),$D28) -> #REF! | I28: 55MEC2403010 | J28: MEC2403010||Máy đưa bo Vrack Line rửa nguyên vật liệu | K28: =SUMIFS(INDIRECT(""&$E$3&"!"&"$C$6"):INDIRECT(""&$E$3&"!"&"$C$2000"),INDIRECT(""&$E$3&"!"&"$B$6"):INDIRECT(""&$E$3&"!"&"$B$2000"),$I28) -> #REF! | L28: =IFERROR(VLOOKUP($I28,$D$5:$D$100,1,FALSE),".") -> . | M28: =IFERROR(VLOOKUP($I28,$A$5:$A$200,1,FALSE),".") -> 55MEC2403010
A29: 55MEC2209010 | F29: =IF(IFERROR(VLOOKUP($D29,$A$5:$A$6000,1,FALSE),"x")<>"x","Y",".") -> . | G29: =SUMIFS(INDIRECT(""&$E$3&"!"&"$C$6"):INDIRECT(""&$E$3&"!"&"$C$20000"),INDIRECT(""&$E$3&"!"&"$B$6"):INDIRECT(""&$E$3&"!"&"$B$20000"),$D29) -> #REF! | I29: 55MEC2403011 | J29: MEC2403011||Máy nhận bo Vrack Line rửa nguyên vật liệu | K29: =SUMIFS(INDIRECT(""&$E$3&"!"&"$C$6"):INDIRECT(""&$E$3&"!"&"$C$2000"),INDIRECT(""&$E$3&"!"&"$B$6"):INDIRECT(""&$E$3&"!"&"$B$2000"),$I29) -> #REF! | L29: =IFERROR(VLOOKUP($I29,$D$5:$D$100,1,FALSE),".") -> . | M29: =IFERROR(VLOOKUP($I29,$A$5:$A$200,1,FALSE),".") -> 55MEC2403011
A30: 55MEC2209011 | F30: =IF(IFERROR(VLOOKUP($D30,$A$5:$A$6000,1,FALSE),"x")<>"x","Y",".") -> . | G30: =SUMIFS(INDIRECT(""&$E$3&"!"&"$C$6"):INDIRECT(""&$E$3&"!"&"$C$20000"),INDIRECT(""&$E$3&"!"&"$B$6"):INDIRECT(""&$E$3&"!"&"$B$20000"),$D30) -> #REF! | I30: 55MEC2403012 | J30: MEC2403012||Máy nhận bo Vrack Line LPR ＃3 | K30: =SUMIFS(INDIRECT(""&$E$3&"!"&"$C$6"):INDIRECT(""&$E$3&"!"&"$C$2000"),INDIRECT(""&$E$3&"!"&"$B$6"):INDIRECT(""&$E$3&"!"&"$B$2000"),$I30) -> #REF! | L30: =IFERROR(VLOOKUP($I30,$D$5:$D$100,1,FALSE),".") -> . | M30: =IFERROR(VLOOKUP($I30,$A$5:$A$200,1,FALSE),".") -> .
A31: 55MEC2210004 | F31: =IF(IFERROR(VLOOKUP($D31,$A$5:$A$6000,1,FALSE),"x")<>"x","Y",".") -> . | G31: =SUMIFS(INDIRECT(""&$E$3&"!"&"$C$6"):INDIRECT(""&$E$3&"!"&"$C$20000"),INDIRECT(""&$E$3&"!"&"$B$6"):INDIRECT(""&$E$3&"!"&"$B$20000"),$D31) -> #REF! | I31: 55MEC2403013 | J31: MEC2403013||Máy nhận bo Vrack Line LPR ＃4 | K31: =SUMIFS(INDIRECT(""&$E$3&"!"&"$C$6"):INDIRECT(""&$E$3&"!"&"$C$2000"),INDIRECT(""&$E$3&"!"&"$B$6"):INDIRECT(""&$E$3&"!"&"$B$2000"),$I31) -> #REF! | L31: =IFERROR(VLOOKUP($I31,$D$5:$D$100,1,FALSE),".") -> . | M31: =IFERROR(VLOOKUP($I31,$A$5:$A$200,1,FALSE),".") -> .
A32: 55MEC2211007 | F32: =IF(IFERROR(VLOOKUP($D32,$A$5:$A$6000,1,FALSE),"x")<>"x","Y",".") -> . | G32: =SUMIFS(INDIRECT(""&$E$3&"!"&"$C$6"):INDIRECT(""&$E$3&"!"&"$C$20000"),INDIRECT(""&$E$3&"!"&"$B$6"):INDIRECT(""&$E$3&"!"&"$B$20000"),$D32) -> #REF! | I32: 55MEC2403014 | J32: MEC2403014||Máy đưa bo Vrack Line Tự động chụp sáng #1 | K32: =SUMIFS(INDIRECT(""&$E$3&"!"&"$C$6"):INDIRECT(""&$E$3&"!"&"$C$2000"),INDIRECT(""&$E$3&"!"&"$B$6"):INDIRECT(""&$E$3&"!"&"$B$2000"),$I32) -> #REF! | L32: =IFERROR(VLOOKUP($I32,$D$5:$D$100,1,FALSE),".") -> . | M32: =IFERROR(VLOOKUP($I32,$A$5:$A$200,1,FALSE),".") -> .
A33: 55MEC2301010 | F33: =IF(IFERROR(VLOOKUP($D33,$A$5:$A$6000,1,FALSE),"x")<>"x","Y",".") -> . | G33: =SUMIFS(INDIRECT(""&$E$3&"!"&"$C$6"):INDIRECT(""&$E$3&"!"&"$C$20000"),INDIRECT(""&$E$3&"!"&"$B$6"):INDIRECT(""&$E$3&"!"&"$B$20000"),$D33) -> #REF! | I33: 55MEC2403025 | J33: MEC2403025||受取機（平積・合紙） Máy nhận bo (H rack + IC) Inline AOI MEC2403025 | K33: =SUMIFS(INDIRECT(""&$E$3&"!"&"$C$6"):INDIRECT(""&$E$3&"!"&"$C$2000"),INDIRECT(""&$E$3&"!"&"$B$6"):INDIRECT(""&$E$3&"!"&"$B$2000"),$I33) -> #REF! | L33: =IFERROR(VLOOKUP($I33,$D$5:$D$100,1,FALSE),".") -> . | M33: =IFERROR(VLOOKUP($I33,$A$5:$A$200,1,FALSE),".") -> 55MEC2403025
A34: 55MEC2303015 | F34: =IF(IFERROR(VLOOKUP($D34,$A$5:$A$6000,1,FALSE),"x")<>"x","Y",".") -> . | G34: =SUMIFS(INDIRECT(""&$E$3&"!"&"$C$6"):INDIRECT(""&$E$3&"!"&"$C$20000"),INDIRECT(""&$E$3&"!"&"$B$6"):INDIRECT(""&$E$3&"!"&"$B$20000"),$D34) -> #REF! | I34: 55MEC2403026 | J34: MEC2403026||受取機（平積・合紙） Máy nhận bo (H rack + IC) Inline AOI MEC2403026 | K34: =SUMIFS(INDIRECT(""&$E$3&"!"&"$C$6"):INDIRECT(""&$E$3&"!"&"$C$2000"),INDIRECT(""&$E$3&"!"&"$B$6"):INDIRECT(""&$E$3&"!"&"$B$2000"),$I34) -> #REF! | L34: =IFERROR(VLOOKUP($I34,$D$5:$D$100,1,FALSE),".") -> . | M34: =IFERROR(VLOOKUP($I34,$A$5:$A$200,1,FALSE),".") -> 55MEC2403026
A35: 55MEC2307001 | F35: =IF(IFERROR(VLOOKUP($D35,$A$5:$A$6000,1,FALSE),"x")<>"x","Y",".") -> . | G35: =SUMIFS(INDIRECT(""&$E$3&"!"&"$C$6"):INDIRECT(""&$E$3&"!"&"$C$20000"),INDIRECT(""&$E$3&"!"&"$B$6"):INDIRECT(""&$E$3&"!"&"$B$20000"),$D35) -> #REF! | I35: 55MEC2403028 | J35: MEC2403028||Máy nhận bo V rack TYPE 4 Line Mài sau ép lớp | K35: =SUMIFS(INDIRECT(""&$E$3&"!"&"$C$6"):INDIRECT(""&$E$3&"!"&"$C$2000"),INDIRECT(""&$E$3&"!"&"$B$6"):INDIRECT(""&$E$3&"!"&"$B$2000"),$I35) -> #REF! | L35: =IFERROR(VLOOKUP($I35,$D$5:$D$100,1,FALSE),".") -> . | M35: =IFERROR(VLOOKUP($I35,$A$5:$A$200,1,FALSE),".") -> .
... A114: 55MEC2403039 | F114: =IF(IFERROR(VLOOKUP($D114,$A$5:$A$6000,1,FALSE),"x")<>"x","Y",".") -> . | G114: =SUMIFS(INDIRECT(""&$E$3&"!"&"$C$6"):INDIRECT(""&$E$3&"!"&"$C$20000"),INDIRECT(""&$E$3&"!"&"$B$6"):INDIRECT(""&$E$3&"!"&"$B$20000"),$D114) -> #REF! | I114: 55MEC2410006 | J114: MEC2410006||Dán màng tầng 2 - Máy nhận bo MEC2102017 | K114: =SUMIFS(INDIRECT(""&$E$3&"!"&"$C$6"):INDIRECT(""&$E$3&"!"&"$C$2000"),INDIRECT(""&$E$3&"!"&"$B$6"):INDIRECT(""&$E$3&"!"&"$B$2000"),$I114) -> #REF! | L114: =IFERROR(VLOOKUP($I114,$D$5:$D$100,1,FALSE),".") -> . | M114: =IFERROR(VLOOKUP($I114,$A$5:$A$200,1,FALSE),".") -> .
A115: 55MEC2403043 | I115: 55MEC2410008 | J115: MEC2410008||Dự án Robot an ninh (T10 -> T12/2024: Bác chủ tịch | K115: =SUMIFS(INDIRECT(""&$E$3&"!"&"$C$6"):INDIRECT(""&$E$3&"!"&"$C$2000"),INDIRECT(""&$E$3&"!"&"$B$6"):INDIRECT(""&$E$3&"!"&"$B$2000"),$I115) -> #REF! | L115: =IFERROR(VLOOKUP($I115,$D$5:$D$100,1,FALSE),".") -> . | M115: =IFERROR(VLOOKUP($I115,$A$5:$A$200,1,FALSE),".") -> 55MEC2410008
A116: 55MEC2403071 | I116: 55MEC2410011 | J116: MEC2410011||Carrier Device (Load & Unload) for ML605 laser processing, Fact.4 MKVC #1 | K116: =SUMIFS(INDIRECT(""&$E$3&"!"&"$C$6"):INDIRECT(""&$E$3&"!"&"$C$2000"),INDIRECT(""&$E$3&"!"&"$B$6"):INDIRECT(""&$E$3&"!"&"$B$2000"),$I116) -> #REF! | L116: =IFERROR(VLOOKUP($I116,$D$5:$D$100,1,FALSE),".") -> . | M116: =IFERROR(VLOOKUP($I116,$A$5:$A$200,1,FALSE),".") -> 55MEC2410011
A117: 55MEC2404004 | I117: 55MEC2410020 | J117: MEC2410020||Carrier Device (Load & Unload) for ML605 laser processing, Fact.4 MKVC #10 | K117: =SUMIFS(INDIRECT(""&$E$3&"!"&"$C$6"):INDIRECT(""&$E$3&"!"&"$C$2000"),INDIRECT(""&$E$3&"!"&"$B$6"):INDIRECT(""&$E$3&"!"&"$B$2000"),$I117) -> #REF! | L117: =IFERROR(VLOOKUP($I117,$D$5:$D$100,1,FALSE),".") -> . | M117: =IFERROR(VLOOKUP($I117,$A$5:$A$200,1,FALSE),".") -> .
A118: 55MEC2404005 | I118: 55MEC2410021 | J118: MEC2410021||Dịch vụ cải tiến máy nhận bo dùng xe V, Tạo mạch line Des #1 - #4 và mạ đồng , Line Desmear#5 | K118: =SUMIFS(INDIRECT(""&$E$3&"!"&"$C$6"):INDIRECT(""&$E$3&"!"&"$C$2000"),INDIRECT(""&$E$3&"!"&"$B$6"):INDIRECT(""&$E$3&"!"&"$B$2000"),$I118) -> #REF! | L118: =IFERROR(VLOOKUP($I118,$D$5:$D$100,1,FALSE),".") -> . | M118: =IFERROR(VLOOKUP($I118,$A$5:$A$200,1,FALSE),".") -> 55MEC2410021
...

Sheet FORM TẠM
C1: 7
C2: 2026
G3: =DATE(C2,C1,1) -> 46204 | H3: =G3 + 1 -> 46205 | I3: =H3 + 1 -> 46206 | J3: =I3 + 1 -> 46207 | K3: =J3 + 1 -> 46208 | L3: =K3 + 1 -> 46209 | M3: =L3 + 1 -> 46210 | N3: =M3 + 1 -> 46211 | O3: =N3 + 1 -> 46212 | ... AK3: =AJ3 + 1 -> 46234 | AM3: {=_xludf.UNIQUE(D4:D1000)} -> #NAME? | AN3: AGV
B4: =IFERROR(__xludf.DUMMYFUNCTION("QUERY( TS_Jul!A:AJ, ""select * where D = 'Check MDA'"", 0 )"),1) -> 1 | C4: =IFERROR(__xludf.DUMMYFUNCTION("""COMPUTED_VALUE"""),"Nguyễn Minh Tiến") -> Nguyễn Minh Tiến | D4: =IFERROR(__xludf.DUMMYFUNCTION("""COMPUTED_VALUE"""),"AGV") -> AGV | E4: =IFERROR(__xludf.DUMMYFUNCTION("""COMPUTED_VALUE"""),"Check MDA") -> Check MDA | AM4: #NAME? | AN4: AUTO
B5: =IFERROR(__xludf.DUMMYFUNCTION("""COMPUTED_VALUE"""),2) -> 2 | C5: =IFERROR(__xludf.DUMMYFUNCTION("""COMPUTED_VALUE"""),"Nghiêm Xuân Thành") -> Nghiêm Xuân Thành | D5: =IFERROR(__xludf.DUMMYFUNCTION("""COMPUTED_VALUE"""),"AUTO_TK cơ") -> AUTO_TK cơ | E5: =IFERROR(__xludf.DUMMYFUNCTION("""COMPUTED_VALUE"""),"Check MDA") -> Check MDA | AM5: #NAME? | AN5: AUTO
B6: =IFERROR(__xludf.DUMMYFUNCTION("""COMPUTED_VALUE"""),3) -> 3 | C6: =IFERROR(__xludf.DUMMYFUNCTION("""COMPUTED_VALUE"""),"Trần Đức Hải") -> Trần Đức Hải | D6: =IFERROR(__xludf.DUMMYFUNCTION("""COMPUTED_VALUE"""),"AGV") -> AGV | E6: =IFERROR(__xludf.DUMMYFUNCTION("""COMPUTED_VALUE"""),"Check MDA") -> Check MDA | AM6: #NAME? | AN6: IOT
B7: =IFERROR(__xludf.DUMMYFUNCTION("""COMPUTED_VALUE"""),4) -> 4 | C7: =IFERROR(__xludf.DUMMYFUNCTION("""COMPUTED_VALUE"""),"Ngô Đức Thành") -> Ngô Đức Thành | D7: =IFERROR(__xludf.DUMMYFUNCTION("""COMPUTED_VALUE"""),"AUTO_TK cơ") -> AUTO_TK cơ | E7: =IFERROR(__xludf.DUMMYFUNCTION("""COMPUTED_VALUE"""),"Check MDA") -> Check MDA | AM7: #NAME? | AN7: AUTO
B8: =IFERROR(__xludf.DUMMYFUNCTION("""COMPUTED_VALUE"""),5) -> 5 | C8: =IFERROR(__xludf.DUMMYFUNCTION("""COMPUTED_VALUE"""),"Trần Việt Lâm") -> Trần Việt Lâm | D8: =IFERROR(__xludf.DUMMYFUNCTION("""COMPUTED_VALUE"""),"AUTO_TK điện") -> AUTO_TK điện | E8: =IFERROR(__xludf.DUMMYFUNCTION("""COMPUTED_VALUE"""),"Check MDA") -> Check MDA | AM8: #NAME? | AN8: ICT
B9: =IFERROR(__xludf.DUMMYFUNCTION("""COMPUTED_VALUE"""),6) -> 6 | C9: =IFERROR(__xludf.DUMMYFUNCTION("""COMPUTED_VALUE"""),"Nguyễn Trí Việt Anh") -> Nguyễn Trí Việt Anh | D9: =IFERROR(__xludf.DUMMYFUNCTION("""COMPUTED_VALUE"""),"AUTO_TK điện") -> AUTO_TK điện | E9: =IFERROR(__xludf.DUMMYFUNCTION("""COMPUTED_VALUE"""),"Check MDA") -> Check MDA | AM9: #NAME? | AN9: R&D
B10: =IFERROR(__xludf.DUMMYFUNCTION("""COMPUTED_VALUE"""),7) -> 7 | C10: =IFERROR(__xludf.DUMMYFUNCTION("""COMPUTED_VALUE"""),"Vũ Minh Đức") -> Vũ Minh Đức | D10: =IFERROR(__xludf.DUMMYFUNCTION("""COMPUTED_VALUE"""),"IOT") -> IOT | E10: =IFERROR(__xludf.DUMMYFUNCTION("""COMPUTED_VALUE"""),"Check MDA") -> Check MDA | AM10: #NAME? | AN10: AUTO
B11: =IFERROR(__xludf.DUMMYFUNCTION("""COMPUTED_VALUE"""),8) -> 8 | C11: =IFERROR(__xludf.DUMMYFUNCTION("""COMPUTED_VALUE"""),"Trần Minh Tùng") -> Trần Minh Tùng | D11: =IFERROR(__xludf.DUMMYFUNCTION("""COMPUTED_VALUE"""),"AGV") -> AGV | E11: =IFERROR(__xludf.DUMMYFUNCTION("""COMPUTED_VALUE"""),"Check MDA") -> Check MDA | AM11: #NAME? | AN11: AGV
B12: =IFERROR(__xludf.DUMMYFUNCTION("""COMPUTED_VALUE"""),9) -> 9 | C12: =IFERROR(__xludf.DUMMYFUNCTION("""COMPUTED_VALUE"""),"Phí Văn Tuấn") -> Phí Văn Tuấn | D12: =IFERROR(__xludf.DUMMYFUNCTION("""COMPUTED_VALUE"""),"AUTO_LR") -> AUTO_LR | E12: =IFERROR(__xludf.DUMMYFUNCTION("""COMPUTED_VALUE"""),"Check MDA") -> Check MDA | AM12: #NAME? | AN12: Trung Hưng
B13: =IFERROR(__xludf.DUMMYFUNCTION("""COMPUTED_VALUE"""),10) -> 10 | C13: =IFERROR(__xludf.DUMMYFUNCTION("""COMPUTED_VALUE"""),"Nguyễn Văn Việt Anh") -> Nguyễn Văn Việt Anh | D13: =IFERROR(__xludf.DUMMYFUNCTION("""COMPUTED_VALUE"""),"AGV") -> AGV | E13: =IFERROR(__xludf.DUMMYFUNCTION("""COMPUTED_VALUE"""),"Check MDA") -> Check MDA | AM13: #NAME? | AN13: Trung Hưng
B14: =IFERROR(__xludf.DUMMYFUNCTION("""COMPUTED_VALUE"""),11) -> 11 | C14: =IFERROR(__xludf.DUMMYFUNCTION("""COMPUTED_VALUE"""),"Trần Duy Anh") -> Trần Duy Anh | D14: =IFERROR(__xludf.DUMMYFUNCTION("""COMPUTED_VALUE"""),"ICT") -> ICT | E14: =IFERROR(__xludf.DUMMYFUNCTION("""COMPUTED_VALUE"""),"Check MDA") -> Check MDA | AM14: #NAME?
B15: =IFERROR(__xludf.DUMMYFUNCTION("""COMPUTED_VALUE"""),12) -> 12 | C15: =IFERROR(__xludf.DUMMYFUNCTION("""COMPUTED_VALUE"""),"Trần Đức Nam") -> Trần Đức Nam | D15: =IFERROR(__xludf.DUMMYFUNCTION("""COMPUTED_VALUE"""),"ICT") -> ICT | E15: =IFERROR(__xludf.DUMMYFUNCTION("""COMPUTED_VALUE"""),"Check MDA") -> Check MDA | AM15: #NAME?
B16: =IFERROR(__xludf.DUMMYFUNCTION("""COMPUTED_VALUE"""),13) -> 13 | C16: =IFERROR(__xludf.DUMMYFUNCTION("""COMPUTED_VALUE"""),"Hoàng Anh Minh") -> Hoàng Anh Minh | D16: =IFERROR(__xludf.DUMMYFUNCTION("""COMPUTED_VALUE"""),"AGV") -> AGV | E16: =IFERROR(__xludf.DUMMYFUNCTION("""COMPUTED_VALUE"""),"Check MDA") -> Check MDA | AM16: #NAME?
B17: =IFERROR(__xludf.DUMMYFUNCTION("""COMPUTED_VALUE"""),14) -> 14 | C17: =IFERROR(__xludf.DUMMYFUNCTION("""COMPUTED_VALUE"""),"Nguyễn Tiến Đạt") -> Nguyễn Tiến Đạt | D17: =IFERROR(__xludf.DUMMYFUNCTION("""COMPUTED_VALUE"""),"ICT") -> ICT | E17: =IFERROR(__xludf.DUMMYFUNCTION("""COMPUTED_VALUE"""),"Check MDA") -> Check MDA | AM17: #NAME?
B18: =IFERROR(__xludf.DUMMYFUNCTION("""COMPUTED_VALUE"""),15) -> 15 | C18: =IFERROR(__xludf.DUMMYFUNCTION("""COMPUTED_VALUE"""),"Hoàng Trọng Phi") -> Hoàng Trọng Phi | D18: =IFERROR(__xludf.DUMMYFUNCTION("""COMPUTED_VALUE"""),"AUTO_TK cơ") -> AUTO_TK cơ | E18: =IFERROR(__xludf.DUMMYFUNCTION("""COMPUTED_VALUE"""),"Check MDA") -> Check MDA | AM18: #NAME?
B19: =IFERROR(__xludf.DUMMYFUNCTION("""COMPUTED_VALUE"""),16) -> 16 | C19: =IFERROR(__xludf.DUMMYFUNCTION("""COMPUTED_VALUE"""),"Nguyễn Xuân Minh") -> Nguyễn Xuân Minh | D19: =IFERROR(__xludf.DUMMYFUNCTION("""COMPUTED_VALUE"""),"ICT") -> ICT | E19: =IFERROR(__xludf.DUMMYFUNCTION("""COMPUTED_VALUE"""),"Check MDA") -> Check MDA
B20: =IFERROR(__xludf.DUMMYFUNCTION("""COMPUTED_VALUE"""),17) -> 17 | C20: =IFERROR(__xludf.DUMMYFUNCTION("""COMPUTED_VALUE"""),"Vương Trung Kiên") -> Vương Trung Kiên | D20: =IFERROR(__xludf.DUMMYFUNCTION("""COMPUTED_VALUE"""),"AGV") -> AGV | E20: =IFERROR(__xludf.DUMMYFUNCTION("""COMPUTED_VALUE"""),"Check MDA") -> Check MDA
B21: =IFERROR(__xludf.DUMMYFUNCTION("""COMPUTED_VALUE"""),18) -> 18 | C21: =IFERROR(__xludf.DUMMYFUNCTION("""COMPUTED_VALUE"""),"Hồ Đức Trung") -> Hồ Đức Trung | D21: =IFERROR(__xludf.DUMMYFUNCTION("""COMPUTED_VALUE"""),"ICT") -> ICT | E21: =IFERROR(__xludf.DUMMYFUNCTION("""COMPUTED_VALUE"""),"Check MDA") -> Check MDA
B22: =IFERROR(__xludf.DUMMYFUNCTION("""COMPUTED_VALUE"""),19) -> 19 | C22: =IFERROR(__xludf.DUMMYFUNCTION("""COMPUTED_VALUE"""),"Đinh Công Hoàng") -> Đinh Công Hoàng | D22: =IFERROR(__xludf.DUMMYFUNCTION("""COMPUTED_VALUE"""),"AGV") -> AGV | E22: =IFERROR(__xludf.DUMMYFUNCTION("""COMPUTED_VALUE"""),"Check MDA") -> Check MDA
B23: =IFERROR(__xludf.DUMMYFUNCTION("""COMPUTED_VALUE"""),20) -> 20 | C23: =IFERROR(__xludf.DUMMYFUNCTION("""COMPUTED_VALUE"""),"Bùi Khánh Huy") -> Bùi Khánh Huy | D23: =IFERROR(__xludf.DUMMYFUNCTION("""COMPUTED_VALUE"""),"AUTO_TK cơ") -> AUTO_TK cơ | E23: =IFERROR(__xludf.DUMMYFUNCTION("""COMPUTED_VALUE"""),"Check MDA") -> Check MDA
B24: =IFERROR(__xludf.DUMMYFUNCTION("""COMPUTED_VALUE"""),21) -> 21 | C24: =IFERROR(__xludf.DUMMYFUNCTION("""COMPUTED_VALUE"""),"Nguyễn Văn Quỳnh") -> Nguyễn Văn Quỳnh | D24: =IFERROR(__xludf.DUMMYFUNCTION("""COMPUTED_VALUE"""),"ICT") -> ICT | E24: =IFERROR(__xludf.DUMMYFUNCTION("""COMPUTED_VALUE"""),"Check MDA") -> Check MDA
B25: =IFERROR(__xludf.DUMMYFUNCTION("""COMPUTED_VALUE"""),22) -> 22 | C25: =IFERROR(__xludf.DUMMYFUNCTION("""COMPUTED_VALUE"""),"Lý Ngọc Hiếu") -> Lý Ngọc Hiếu | D25: =IFERROR(__xludf.DUMMYFUNCTION("""COMPUTED_VALUE"""),"AUTO_LR") -> AUTO_LR | E25: =IFERROR(__xludf.DUMMYFUNCTION("""COMPUTED_VALUE"""),"Check MDA") -> Check MDA
B26: =IFERROR(__xludf.DUMMYFUNCTION("""COMPUTED_VALUE"""),23) -> 23 | C26: =IFERROR(__xludf.DUMMYFUNCTION("""COMPUTED_VALUE"""),"Phí Văn Nam") -> Phí Văn Nam | D26: =IFERROR(__xludf.DUMMYFUNCTION("""COMPUTED_VALUE"""),"AUTO_LR") -> AUTO_LR | E26: =IFERROR(__xludf.DUMMYFUNCTION("""COMPUTED_VALUE"""),"Check MDA") -> Check MDA
B27: =IFERROR(__xludf.DUMMYFUNCTION("""COMPUTED_VALUE"""),24) -> 24 | C27: =IFERROR(__xludf.DUMMYFUNCTION("""COMPUTED_VALUE"""),"Lương Văn Trường") -> Lương Văn Trường | D27: =IFERROR(__xludf.DUMMYFUNCTION("""COMPUTED_VALUE"""),"AUTO_TK cơ") -> AUTO_TK cơ | E27: =IFERROR(__xludf.DUMMYFUNCTION("""COMPUTED_VALUE"""),"Check MDA") -> Check MDA
B28: =IFERROR(__xludf.DUMMYFUNCTION("""COMPUTED_VALUE"""),25) -> 25 | C28: =IFERROR(__xludf.DUMMYFUNCTION("""COMPUTED_VALUE"""),"Lê Quang Huy") -> Lê Quang Huy | D28: =IFERROR(__xludf.DUMMYFUNCTION("""COMPUTED_VALUE"""),"ICT") -> ICT | E28: =IFERROR(__xludf.DUMMYFUNCTION("""COMPUTED_VALUE"""),"Check MDA") -> Check MDA
B29: =IFERROR(__xludf.DUMMYFUNCTION("""COMPUTED_VALUE"""),26) -> 26 | C29: =IFERROR(__xludf.DUMMYFUNCTION("""COMPUTED_VALUE"""),"Nguyến Thái Thường") -> Nguyến Thái Thường | D29: =IFERROR(__xludf.DUMMYFUNCTION("""COMPUTED_VALUE"""),"AUTO_TK điện") -> AUTO_TK điện | E29: =IFERROR(__xludf.DUMMYFUNCTION("""COMPUTED_VALUE"""),"Check MDA") -> Check MDA
B30: =IFERROR(__xludf.DUMMYFUNCTION("""COMPUTED_VALUE"""),27) -> 27 | C30: =IFERROR(__xludf.DUMMYFUNCTION("""COMPUTED_VALUE"""),"Nguyễn Tuấn Anh") -> Nguyễn Tuấn Anh | D30: =IFERROR(__xludf.DUMMYFUNCTION("""COMPUTED_VALUE"""),"AGV") -> AGV | E30: =IFERROR(__xludf.DUMMYFUNCTION("""COMPUTED_VALUE"""),"Check MDA") -> Check MDA
B31: =IFERROR(__xludf.DUMMYFUNCTION("""COMPUTED_VALUE"""),28) -> 28 | C31: =IFERROR(__xludf.DUMMYFUNCTION("""COMPUTED_VALUE"""),"Nguyễn Đồng Tuân") -> Nguyễn Đồng Tuân | D31: =IFERROR(__xludf.DUMMYFUNCTION("""COMPUTED_VALUE"""),"AUTO_LR") -> AUTO_LR | E31: =IFERROR(__xludf.DUMMYFUNCTION("""COMPUTED_VALUE"""),"Check MDA") -> Check MDA
B32: =IFERROR(__xludf.DUMMYFUNCTION("""COMPUTED_VALUE"""),29) -> 29 | C32: =IFERROR(__xludf.DUMMYFUNCTION("""COMPUTED_VALUE"""),"Nguyễn Thế Thắng") -> Nguyễn Thế Thắng | D32: =IFERROR(__xludf.DUMMYFUNCTION("""COMPUTED_VALUE"""),"AUTO_LR") -> AUTO_LR | E32: =IFERROR(__xludf.DUMMYFUNCTION("""COMPUTED_VALUE"""),"Check MDA") -> Check MDA
B33: =IFERROR(__xludf.DUMMYFUNCTION("""COMPUTED_VALUE"""),30) -> 30 | C33: =IFERROR(__xludf.DUMMYFUNCTION("""COMPUTED_VALUE"""),"Hoàng Văn Tuấn") -> Hoàng Văn Tuấn | D33: =IFERROR(__xludf.DUMMYFUNCTION("""COMPUTED_VALUE"""),"AUTO_TK điện") -> AUTO_TK điện | E33: =IFERROR(__xludf.DUMMYFUNCTION("""COMPUTED_VALUE"""),"Check MDA") -> Check MDA
B34: =IFERROR(__xludf.DUMMYFUNCTION("""COMPUTED_VALUE"""),31) -> 31 | C34: =IFERROR(__xludf.DUMMYFUNCTION("""COMPUTED_VALUE"""),"Đỗ Thanh Quang") -> Đỗ Thanh Quang | D34: =IFERROR(__xludf.DUMMYFUNCTION("""COMPUTED_VALUE"""),"AUTO_TK điện") -> AUTO_TK điện | E34: =IFERROR(__xludf.DUMMYFUNCTION("""COMPUTED_VALUE"""),"Check MDA") -> Check MDA
B35: =IFERROR(__xludf.DUMMYFUNCTION("""COMPUTED_VALUE"""),32) -> 32 | C35: =IFERROR(__xludf.DUMMYFUNCTION("""COMPUTED_VALUE"""),"Tạ Minh Lộc") -> Tạ Minh Lộc | D35: =IFERROR(__xludf.DUMMYFUNCTION("""COMPUTED_VALUE"""),"AUTO_LR") -> AUTO_LR | E35: =IFERROR(__xludf.DUMMYFUNCTION("""COMPUTED_VALUE"""),"Check MDA") -> Check MDA
B36: =IFERROR(__xludf.DUMMYFUNCTION("""COMPUTED_VALUE"""),33) -> 33 | C36: =IFERROR(__xludf.DUMMYFUNCTION("""COMPUTED_VALUE"""),"Võ Văn Giang") -> Võ Văn Giang | D36: =IFERROR(__xludf.DUMMYFUNCTION("""COMPUTED_VALUE"""),"AUTO_TK cơ") -> AUTO_TK cơ | E36: =IFERROR(__xludf.DUMMYFUNCTION("""COMPUTED_VALUE"""),"Check MDA") -> Check MDA
B37: =IFERROR(__xludf.DUMMYFUNCTION("""COMPUTED_VALUE"""),34) -> 34 | C37: =IFERROR(__xludf.DUMMYFUNCTION("""COMPUTED_VALUE"""),"Phạm Đình Chiến") -> Phạm Đình Chiến | D37: =IFERROR(__xludf.DUMMYFUNCTION("""COMPUTED_VALUE"""),"AUTO_TK điện") -> AUTO_TK điện | E37: =IFERROR(__xludf.DUMMYFUNCTION("""COMPUTED_VALUE"""),"Check MDA") -> Check MDA
B38: =IFERROR(__xludf.DUMMYFUNCTION("""COMPUTED_VALUE"""),35) -> 35 | C38: =IFERROR(__xludf.DUMMYFUNCTION("""COMPUTED_VALUE"""),"Nguyễn Đắc Phú") -> Nguyễn Đắc Phú | D38: =IFERROR(__xludf.DUMMYFUNCTION("""COMPUTED_VALUE"""),"AUTO_TK cơ") -> AUTO_TK cơ | E38: =IFERROR(__xludf.DUMMYFUNCTION("""COMPUTED_VALUE"""),"Check MDA") -> Check MDA
B39: =IFERROR(__xludf.DUMMYFUNCTION("""COMPUTED_VALUE"""),36) -> 36 | C39: =IFERROR(__xludf.DUMMYFUNCTION("""COMPUTED_VALUE"""),"Nguyễn Văn Hùng") -> Nguyễn Văn Hùng | D39: =IFERROR(__xludf.DUMMYFUNCTION("""COMPUTED_VALUE"""),"AUTO_LR") -> AUTO_LR | E39: =IFERROR(__xludf.DUMMYFUNCTION("""COMPUTED_VALUE"""),"Check MDA") -> Check MDA
B40: =IFERROR(__xludf.DUMMYFUNCTION("""COMPUTED_VALUE"""),37) -> 37 | C40: =IFERROR(__xludf.DUMMYFUNCTION("""COMPUTED_VALUE"""),"Trần Minh Tiến") -> Trần Minh Tiến | D40: =IFERROR(__xludf.DUMMYFUNCTION("""COMPUTED_VALUE"""),"AUTO_TK cơ") -> AUTO_TK cơ | E40: =IFERROR(__xludf.DUMMYFUNCTION("""COMPUTED_VALUE"""),"Check MDA") -> Check MDA
...

Sheet Email
A1: Tên | B1: Email
A2: Nguyễn Minh Tiến | B2: tien.nguyenminh@meiko.vn
A3: Nguyễn Trọng Phi | B3: phi.nguyentrong@meiko.vn
A4: Nguyễn Minh Cường | B4: cuong.nguyenminh@meiko.vn
A5: Nghiêm Xuân Thành | B5: thanh.nghiemxuan@meiko.vn
A6: Trần Đức Hải | B6: hai.tranduc@meiko.vn
A7: Ngô Đức Thành | B7: thanh.ngoduc@meiko.vn
A8: Nguyễn Đình Tuyến | B8: tuyen.nguyendinh@meiko.vn
A9: Trần Việt Lâm | B9: lam.tranviet@meiko.vn
A10: Hoàng Duy Cường | B10: cuong.hoangduy@meiko.vn
A11: Vũ Minh Đức | B11: duc.vuminh@meiko.vn
A12: Phí Văn Tuấn | B12: phituan1411891@gmail.com
... A50: Nguyễn Văn Hùng | B50: jacobihd97@gmail.com
